Workbook

Sheet INSTRUCTIONS
A1: Scenario:
A2: You’re working as a Business Analyst at 2WheelR and are in charge of maintaining the Purchase Data for used 2 wheelers; and earlier today the Founder (yes, the boss herself!) dropped you a quick message: “Hey, I need your help to present the numbers for our fundraising pitch... can you help me get a clean MoM and QoQ view of our purchase data from April till December? I am unable to see the store wise purchases from August onwards. Also the count of purchases in April from your sheet doesn't match the accountant's data. The accountant insists that there are only 45 purchases made for the month of April. Can you take this up on priority!?” Your mission? Dive into the purchase dataset, spot what’s wrong, clean it up, and get those insights ready for her upcoming fundraising pitch. The numbers need to be crisp, accurate, and presentation-ready — because she trusts you to make the data talk.
A4: Sheets
A5: The sheets "APR-24" to "DEC-24" contain the Purchase Data for that particular month.
A6: The data schema is different for sheets APR-24 to JUL-24 and AUG-24 - DEC-24 due a change in SOP of collecting and recording data. Keep this in mind when conducting your analysis
A7: The sheet “Store Code” contains a mapping between each Store Location and its corresponding Store Purchase ID. The Store Purchase ID serves as a prefix applied to the PDN No (Purchase Delivery Note Number) for every store.
A9: Data Schema
A10: The dataset tracks all purchases made by customers across 2WheelR’s various store locations. Below is a quick breakdown of the key columns you’ll find:
A11: Column | B11: Description
A12: Purchase Date | B12: Date when the vehicle was purchased
A13: VEHICLE NO / Reg No | B13: Registration number of the purchased vehicle
A14: MAKE | B14: Manufacturer or brand of the vehicle (e.g., Hero, Honda, Royal Enfield)
A15: Model | B15: The specific model of vehicle offered by the Brand (e.g., Splendor, Activa 5G, Interceptor)
A16: Purchase Location | B16: Store location where the purchase took place
A17: PURCHASED FROM | B17: Name or source from whom the vehicle was purchased
A18: PURCHASE AMOUNT / Purchase Price | B18: Total purchase amount paid for the vehicle
A19: SELLER NAME | B19: Name of the individual or organization that sold the vehicle
A20: Channel | B20: Procurement channel (Online / Walk-in / Partner / Referral etc.)
A21: Seller Type | B21: Category of seller (Individual / Dealer / Corporate etc.)
A22: Inspection (store/home) | B22: Where the inspection was done — at store or at seller’s home
A23: PDN No | B23: Purchase Delivery Note Number - the unique ID for every Purchase Bill generated at each store
A26: Known Issues
A27: Some cells might contain garbage, dummy, or inconsistent data — these are intentional tests of your attention to detail.
A28: A few entries may have formatting errors, typos, or mismatched data types — you might have to standardize them before analysis.
A29: A few entries have missing data points. This data could be recoverable using your ingenuity OR completely irrecoverable by design. Do your best.
A30: Due to the change in SOP of collecting data, Make and Model is merged or missing for a few months' records. Use online resources to recover and segregate the data
A32: Your Tasks
A33: Task 1 | B33: Figure out why store-wise purchase information is missing from August onwards and fix it
A34: Task 2 | B34: Figure out why your purchase count for April doesn't match the actual data from Accountant and fix it
A35: Task 3 | B35: The below needs to be presented using charts. You are free to use any tool of your choice. The quality of presentation for the below metrics is upto your discretion and will be judged seperately. Prepare a MoM and QoQ analysis of the following metrics: - Purchase Count (all stores) - Purchase Count (individual stores) - Total Purchase Price (all stores only) - Average Purchase Price (all stores only) - Top-5 Purchased Makes (all stores only) - Top-5 Purchased Models (all stores only)
A37: Submission Guidelines
A38: After creating a copy of this Google Sheet, all workings need to be done on your copy.
A39: Upload your copy of this sheet and any other files you would like to submit in a Google Drive folder
A40: Label the folder {Your Name - Data Analytics Submission}
A41: Make sure you have given the "Edit" permission to <karan.varma@2wheelr.com>.
A42: Fill the Assignment Submission Form: https://forms.gle/7d7qLMNuvtf9h8Wm7 and paste your folder link there
A43: We acknowledge that some of you are working professionals or have other commitments and may not be able to complete 100% of the tasks. We want to test how you think, attempt the task and present a solution that is comprehensive and structured. So please submit whatever you are able to complete before the deadline. Any blockers or incomplete tasks can be discussed during a follow-up interview if you are shortlisted.

Sheet Task1 Soln - Aug-Dec 2024
A1: Purchase Date | B1: Reg No | C1: Make | D1: Purchase Location | E1: Model | F1: Purchase Price | G1: Channel | H1: Seller Type | I1: Inspection | J1: PDN-Code | K1: PDN-Letter | L1: PDN-Number
A2: 45506 | B2: MH12WQ4898 | C2: Jawa | D2: =_xlfn.XLOOKUP(J2,'Store Code'!B:B,'Store Code'!A:A) -> SOMWAR PETH | E2: 42 Bobber 330CC | F2: 152000 | G2: Walk-in | H2: Customer | I2: Store | J2: C07 | K2: P | L2: 100077
A3: 45506 | B3: MH12UH9147 | C3: Honda | D3: =_xlfn.XLOOKUP(J3,'Store Code'!B:B,'Store Code'!A:A) -> WAKAD | E3: CB350 RS Dual Tone | F3: 65000 | G3: Walk-in | H3: Customer | I3: Store | J3: C02 | K3: P | L3: 100081
A4: 45507 | B4: MH12RD1033 | C4: Honda | D4: =_xlfn.XLOOKUP(J4,'Store Code'!B:B,'Store Code'!A:A) -> RASTA PETH | E4: CB Hornet 160R ABS Deluxe | F4: 28000 | G4: Walk-in | H4: Customer | I4: Store | J4: F01 | K4: P | L4: 100086
A5: 45507 | B5: MH12LN6409 | C5: Royal Enfield | D5: =_xlfn.XLOOKUP(J5,'Store Code'!B:B,'Store Code'!A:A) -> KHARADI | E5: Classic 350cc | F5: 166000 | G5: - | H5: Customer | I5: Store | J5: C01 | K5: P | L5: 100083
A6: 45508 | B6: MH14HV5141 | C6: TVS | D6: =_xlfn.XLOOKUP(J6,'Store Code'!B:B,'Store Code'!A:A) -> RASTA PETH | E6: Radeon Drum | F6: 45500 | G6: Referral | H6: Customer | I6: Store | J6: F01 | K6: P | L6: 100087
A7: 45508 | B7: MH12LB0462 | C7: Honda | D7: =_xlfn.XLOOKUP(J7,'Store Code'!B:B,'Store Code'!A:A) -> RASTA PETH | E7: Shine 125cc | F7: 31000 | G7: Referral | H7: Customer | I7: Store | J7: F01 | K7: P | L7: 100088
A8: 45509 | B8: MH14JZ7086 | C8: Suzuki | D8: =_xlfn.XLOOKUP(J8,'Store Code'!B:B,'Store Code'!A:A) -> WAKAD | E8: Access Fi 125cc Disc alloy bluetooth BS6 | F8: 35300 | G8: Walk-in | H8: Customer | I8: Store | J8: C02 | K8: P | L8: 100082
A9: 45510 | B9: MH14HJ9889 | C9: TVS | D9: =_xlfn.XLOOKUP(J9,'Store Code'!B:B,'Store Code'!A:A) -> WAKAD | E9: Jupiter 110cc | F9: 55000 | G9: OLX | H9: Customer | I9: Store | J9: C02 | K9: P | L9: 100083
A10: 45510 | B10: MH12LB6639 | C10: TVS | D10: =_xlfn.XLOOKUP(J10,'Store Code'!B:B,'Store Code'!A:A) -> RASTA PETH | E10: Scooty Pep+ 90cc | F10: 40500 | G10: - | H10: Customer | I10: Store | J10: F01 | K10: P | L10: 100089
A11: 45511 | B11: MH14JK5260 | C11: Royal Enfield | D11: =_xlfn.XLOOKUP(J11,'Store Code'!B:B,'Store Code'!A:A) -> RASTA PETH | E11: Classic 350 EFI | F11: 5000 | G11: Referral | H11: Customer | I11: Store | J11: F01 | K11: P | L11: 100090
A12: 45511 | B12: MH12LQ8651 | C12: Yamaha | D12: =_xlfn.XLOOKUP(J12,'Store Code'!B:B,'Store Code'!A:A) -> RASTA PETH | E12: Ray 110cc | F12: 20000 | G12: Referral | H12: Agent | I12: Store | J12: F01 | K12: P | L12: 100091
A13: 45512 | B13: MH12VN7775 | C13: TVS | D13: =_xlfn.XLOOKUP(J13,'Store Code'!B:B,'Store Code'!A:A) -> WAKAD | E13: Jupiter 110CC BS6 | F13: 45000 | G13: Google | H13: Customer | I13: Store | J13: C02 | K13: P | L13: 100084
... A422: 45657 | B422: MH12VH3859 | C422: Royal Enfield | D422: =_xlfn.XLOOKUP(J422,'Store Code'!B:B,'Store Code'!A:A) -> RASTA PETH | E422: Bullet 350cc KS EFI Black | F422: 135000 | G422: Walk-in | H422: Customer | I422: Store | J422: F01 | K422: P | L422: 100412

Sheet Task 2 Soln - APR-24
A1: Purchase Date | B1: VEHICLE NO | C1: MAKE or MODEL | D1: Purchase Location | E1: PURCHASED FROM | F1: PURCHASE AMOUNT | G1: SELLER NAME
A2: 45383 | B2: MH14CZ8021 | C2: PLEASURE | D2: WAKAD | E2: SACHIN | F2: 44500 | G2: SURESH MANIKRAO MUNDE
A3: 45383 | B3: MH14JK4374 | C3: SHINE | D3: RASTA PETH | E3: SACHIN | F3: 27000 | G3: AMIT TUKARAM PADWAL | I3: Solution :
A4: 45383 | B4: MH14JK4346 | C4: SHINE | D4: KHARADI | E4: SACHIN | F4: 38000 | G4: RAJKUMAR KUSULAL JAIN | I4: I deleted the garbage dataset which were inflating the count > 45 and updated the inconsistency in dates. After, cleaning the data, now the records match = 45
A5: 45385 | B5: MH14HH2582 | C5: APACHE | D5: RASTA PETH | E5: SACHIN | F5: 59000 | G5: MANOJ DEVRAM ZANJARE
A6: 45385 | B6: MH14GQ2577 | C6: ACCESS 125 | D6: RASTA PETH | E6: SACHIN | F6: 149500 | G6: KALURAM DAMODAR BALGHARE | I6: =COUNTA(A2:A46) -> 45
A7: 45385 | B7: MH14DL9446 | C7: ACTIVA | D7: KHARADI | E7: SACHIN | F7: 27000 | G7: HERAMB THERMOPLASTICS PVT LTD
A8: 45388 | B8: MH14CR0797 | C8: PASSION PRO | D8: RASTA PETH | E8: SACHIN | F8: 91000 | G8: RAMRAO DINKARRAO SHINDE
A9: 45388 | B9: MH12HM292 | C9: SZR | D9: RASTA PETH | E9: SACHIN | F9: 33000 | G9: UMESH BALASAHEB PATIL
A10: 45390 | B10: MH14FZ6221 | C10: UNICORN | D10: KHARADI | E10: SACHIN | F10: 20500 | G10: SANTOSH DATTATRAY BRAHMANKAR
A11: 45390 | B11: MH04HW7586 | C11: MAESTRO | D11: KHARADI | E11: SACHIN | F11: 25000 | G11: KRANTI SONU LAMBOLE
A12: 45390 | B12: MH12LR0449 | C12: PULSAR 220 | D12: RASTA PETH | E12: SACHIN | F12: 59000 | G12: NAVNATH KERU APHALE
A13: 45390 | B13: MH12FM7433 | C13: PULSAR 180 | D13: WAKAD | E13: SACHIN | F13: 19000 | G13: NISHANT SINGH
A14: 45391 | B14: MH14CQ1330 | C14: DIO | D14: RASTA PETH | E14: SACHIN | F14: 44500 | G14: HARISH VISHWANATH CHOUDHARY
A15: 45391 | B15: MH14EN8627 | C15: RADEO | D15: RASTA PETH | E15: SACHIN | F15: 21000 | G15: DATTATRAY VIDHOBA SHINDE
A16: 45394 | B16: MH14ET2734 | C16: ACTIVA | D16: WAKAD | E16: SACHIN | F16: 43200 | G16: SAINATH GABAJI BANKAR
A17: 45394 | B17: MH12KM1169 | C17: RAY | D17: WAKAD | E17: SACHIN | F17: 111000 | G17: NISAR AHMAD ABBAS SHAIKH
A18: 45394 | B18: MH14DV3427 | C18: ACTIVA | D18: RASTA PETH | E18: SACHIN | F18: 30500 | G18: SUNIL DOULATRAO KAKADE
... A27: 45395 | B27: MH14KC6782 | C27: SCOOTY PEP+ | D27: RASTA PETH | E27: CHETAN | F27: 19000 | G27: NAMDEV JADHAV
A28: 45398 | B28: MH12JH4363 | C28: ACCESS | D28: KHARADI | F28: 78000 | G28: KASHMIRA UTKARSH GANDHI
A29: 45401 | B29: MH12QB1317 | C29: ACCESS 125 | D29: RASTA PETH | E29: CHETAN | F29: 10000 | G29: SWAPNIL CHOUGULE
A30: 45408 | B30: MH12TB5565 | C30: JAWA PERAK | D30: RASTA PETH | E30: SALIM | F30: 14000 | G30: TUSHAR DEEPAK BODKE
A31: 45384 | B31: MH12MD0026 | C31: ACTIVA 3G | D31: WAKAD | F31: 22000 | G31: MAYUR SUNIL GHOLAP
A32: 45388 | B32: MH12QH8027 | C32: ACTIVA 5G | D32: WAKAD | F32: 36000 | G32: VIJAY ANNASAHEB NALWADE
A33: 45389 | B33: MH12PF0426 | C33: JUPITER | D33: RASTA PETH | F33: 45000 | G33: SUPRIYA GHULE
A34: 45389 | B34: MH12LS4754 | C34: R15 | D34: KHARADI | F34: 33000
A35: 45390 | B35: MH12JW1304 | C35: PLEASURE | D35: RASTA PETH | F35: 13000 | G35: DEEPALI KURKUTE
A36: 45392 | B36: MH12HH0889 | C36: ACTIVA | D36: KHARADI | F36: 46000 | G36: ANUSAYA MAYAPPA DEVMANE
A37: 45392 | B37: MH12QL3092 | C37: ACTIVA 5G | D37: RASTA PETH | F37: 69000 | G37: SANJAY ROHIDAS GAIKWAD
A38: 45393 | B38: MH12RU6362 | C38: APACHE RTR 160 | D38: RASTA PETH | F38: 15000 | G38: KALYAN ADSULE
A39: 45398 | B39: MH14HJ9267 | C39: WEGO | D39: RASTA PETH | F39: 30000 | G39: CHETANKUMAR BAMBORI
A40: 45403 | B40: MH12SS6102 | C40: ACTIVA 6G | D40: WAKAD | F40: 18000 | G40: ARCHANA ASHOK GAIKWAD
A41: 45406 | B41: MH12GX0069 | C41: CBZ XTREME | D41: WAKAD | F41: 48000 | G41: RAHUL SURYAKANT WAGHMODE
A42: 45406 | B42: MH13ED7995 | C42: MT15 | D42: RASTA PETH | F42: 15400 | G42: TUSHAR DATTATRAY CHAVAN
A43: 45407 | B43: MH12PG1332 | C43: CB SHINE SP | D43: RASTA PETH | F43: 13000 | G43: PANDURANG PUNAJI
A44: 45407 | B44: MH12LH4938 | C44: ACTIVA 110 | D44: KHARADI | F44: 27000 | G44: SWANANDI JOSHI
A45: 45408 | B45: MH12VP2031 | C45: VESPA | D45: RASTA PETH | F45: 16000 | G45: MEENAL DEVRAJ SAPKALE
A46: 45412 | B46: MH12RU1885 | C46: ACTIVA 125 | D46: WAKAD | F46: 38000 | G46: BALASAHEB NAMDEV SHENDGE

Sheet MoM-Purchase Count (All Stores)
A3: Row Labels | B3: Count of Purchase Location
A4: Apr | B4: 45
A5: May | B5: 75
A6: Jun | B6: 71
A7: Jul | B7: 91
A8: Aug | B8: 92
A9: Sep | B9: 90
A10: Oct | B10: 102
A11: Nov | B11: 61
A12: Dec | B12: 76
A13: Grand Total | B13: 703

Sheet MoM-Purchase Count (Ind Stores)
A3: Count of Purchase Location | B3: Column Labels
A4: Row Labels | B4: KHARADI | C4: RASTA PETH | D4: SINHAGAD ROAD | E4: SOMWAR PETH | F4: UNDRI | G4: WAKAD | H4: Grand Total
A5: Apr | B5: 12 | C5: 21 | G5: 12 | H5: 45
A6: May | B6: 11 | C6: 54 | D6: 1 | F6: 3 | G6: 6 | H6: 75
A7: Jun | B7: 11 | C7: 37 | D7: 3 | E7: 1 | F7: 4 | G7: 15 | H7: 71
A8: Jul | B8: 11 | C8: 58 | D8: 3 | E8: 2 | F8: 3 | G8: 14 | H8: 91
A9: Aug | B9: 11 | C9: 60 | D9: 1 | E9: 1 | F9: 1 | G9: 18 | H9: 92
A10: Sep | B10: 21 | C10: 54 | F10: 4 | G10: 11 | H10: 90
A11: Oct | B11: 16 | C11: 78 | G11: 8 | H11: 102
A12: Nov | B12: 8 | C12: 41 | G12: 12 | H12: 61
A13: Dec | B13: 8 | C13: 58 | G13: 10 | H13: 76
A14: Grand Total | B14: 109 | C14: 461 | D14: 8 | E14: 4 | F14: 15 | G14: 106 | H14: 703

Sheet MoM-Total Purchase Price
A3: Sum of PURCHASE AMOUNT | B3: Column Labels
A4: Row Labels | B4: KHARADI | C4: RASTA PETH | D4: SINHAGAD ROAD | E4: SOMWAR PETH | F4: UNDRI | G4: WAKAD | H4: Grand Total
A5: Apr | B5: 523700 | C5: 809900 | G5: 531400 | H5: 1865000
A6: May | B6: 557300 | C6: 2876900 | D6: 30000 | F6: 47500 | G6: 541300 | H6: 4053000
A7: Jun | B7: 457100 | C7: 2413800 | D7: 79000 | E7: 27500 | F7: 408000 | G7: 967600 | H7: 4353000
A8: Jul | B8: 792600 | C8: 3365500 | D8: 233500 | E8: 117000 | F8: 249000 | G8: 1022000 | H8: 5779600
A9: Aug | B9: 658000 | C9: 2722400 | D9: 10000 | E9: 152000 | F9: 70000 | G9: 881800 | H9: 4494200
A10: Sep | B10: 1016600 | C10: 3299930 | F10: 298000 | G10: 391900 | H10: 5006430
A11: Oct | B11: 571000 | C11: 3541900 | G11: 363400 | H11: 4476300
A12: Nov | B12: 416700 | C12: 1737900 | G12: 762500 | H12: 2917100
A13: Dec | B13: 337600 | C13: 2511660 | G13: 409500 | H13: 3258760
A14: Grand Total | B14: 5330600 | C14: 23279890 | D14: 352500 | E14: 296500 | F14: 1072500 | G14: 5871400 | H14: 36203390

Sheet MoM-Average Purchase Price
A3: Average of PURCHASE AMOUNT | B3: Column Labels
A4: Row Labels | B4: KHARADI | C4: RASTA PETH | D4: SINHAGAD ROAD | E4: SOMWAR PETH | F4: UNDRI | G4: WAKAD | H4: Grand Total
A5: Apr | B5: 43641.667 | C5: 38566.667 | G5: 44283.333 | H5: 41444.444
A6: May | B6: 50663.636 | C6: 53275.926 | D6: 30000 | F6: 15833.333 | G6: 90216.667 | H6: 54040
A7: Jun | B7: 41554.545 | C7: 65237.838 | D7: 26333.333 | E7: 27500 | F7: 102000 | G7: 64506.667 | H7: 61309.859
A8: Jul | B8: 72054.545 | C8: 58025.862 | D8: 77833.333 | E8: 58500 | F8: 83000 | G8: 73000 | H8: 63512.088
A9: Aug | B9: 59818.182 | C9: 45373.333 | D9: 10000 | E9: 152000 | F9: 70000 | G9: 48988.889 | H9: 48850
A10: Sep | B10: 48409.524 | C10: 61109.815 | F10: 74500 | G10: 35627.273 | H10: 55627
A11: Oct | B11: 35687.5 | C11: 45408.974 | G11: 45425 | H11: 43885.294
A12: Nov | B12: 52087.5 | C12: 42387.805 | G12: 63541.667 | H12: 47821.311
A13: Dec | B13: 42200 | C13: 43304.483 | G13: 40950 | H13: 42878.421
A14: Grand Total | B14: 48904.587 | C14: 50498.677 | D14: 44062.5 | E14: 74125 | F14: 71500 | G14: 55390.566 | H14: 51498.421

Sheet MoM-Top 5 Brands
A3: Row Labels | B3: Count of MAKE
A4: Honda | B4: 260
A5: Apr | B5: 16
A6: May | B6: 21
A7: Jun | B7: 29
A8: Jul | B8: 23
A9: Aug | B9: 33
A10: Sep | B10: 37
A11: Oct | B11: 45
A12: Nov | B12: 22
A13: Dec | B13: 34
A14: TVS | B14: 69
A15: Aug | B15: 15
... A49: Grand Total | B49: 478

Sheet MoM-Top 5 Models
A3: Row Labels | B3: Count of Model
A4: ACTIVA 110 | B4: 42
A5: Apr | B5: 1
A6: May | B6: 4
A7: Jun | B7: 2
A8: Aug | B8: 4
A9: Sep | B9: 6
A10: Oct | B10: 14
A11: Nov | B11: 3
A12: Dec | B12: 8
A13: ACTIVA | B13: 26
A14: Apr | B14: 6
A15: May | B15: 5
... A37: Grand Total | B37: 117

Sheet QoQ-Purchase Count (All Store_
A3: Row Labels | B3: Count of Purchase Location
A4: Q2 | B4: 191
A5: Q3 | B5: 273
A6: Q4 | B6: 239
A7: Grand Total | B7: 703

Sheet QoQ-Purchase Count (Ind Store)
A3: Count of Purchase Location | B3: Column Labels
A4: Row Labels | B4: KHARADI | C4: RASTA PETH | D4: SINHAGAD ROAD | E4: SOMWAR PETH | F4: UNDRI | G4: WAKAD | H4: Grand Total
A5: Q2 | B5: 34 | C5: 112 | D5: 4 | E5: 1 | F5: 7 | G5: 33 | H5: 191
A6: Q3 | B6: 43 | C6: 172 | D6: 4 | E6: 3 | F6: 8 | G6: 43 | H6: 273
A7: Q4 | B7: 32 | C7: 177 | G7: 30 | H7: 239
A8: Grand Total | B8: 109 | C8: 461 | D8: 8 | E8: 4 | F8: 15 | G8: 106 | H8: 703

Sheet QoQ-Total Purchase Price 
A3: Sum of PURCHASE AMOUNT | B3: Column Labels
A4: Row Labels | B4: KHARADI | C4: RASTA PETH | D4: SINHAGAD ROAD | E4: SOMWAR PETH | F4: UNDRI | G4: WAKAD | H4: Grand Total
A5: Q2 | B5: 1538100 | C5: 6100600 | D5: 109000 | E5: 27500 | F5: 455500 | G5: 2040300 | H5: 10271000
A6: Q3 | B6: 2467200 | C6: 9387830 | D6: 243500 | E6: 269000 | F6: 617000 | G6: 2295700 | H6: 15280230
A7: Q4 | B7: 1325300 | C7: 7791460 | G7: 1535400 | H7: 10652160
A8: Grand Total | B8: 5330600 | C8: 23279890 | D8: 352500 | E8: 296500 | F8: 1072500 | G8: 5871400 | H8: 36203390

Sheet QoQ-Average Purchase Price
A3: Average of PURCHASE AMOUNT | B3: Column Labels
A4: Row Labels | B4: KHARADI | C4: RASTA PETH | D4: SINHAGAD ROAD | E4: SOMWAR PETH | F4: UNDRI | G4: WAKAD | H4: Grand Total
A5: Q2 | B5: 45238.235 | C5: 54469.643 | D5: 27250 | E5: 27500 | F5: 65071.429 | G5: 61827.273 | H5: 53774.869
A6: Q3 | B6: 57376.744 | C6: 54580.407 | D6: 60875 | E6: 89666.667 | F6: 77125 | G6: 53388.372 | H6: 55971.538
A7: Q4 | B7: 41415.625 | C7: 44019.548 | G7: 51180 | H7: 44569.707
A8: Grand Total | B8: 48904.587 | C8: 50498.677 | D8: 44062.5 | E8: 74125 | F8: 71500 | G8: 55390.566 | H8: 51498.421

Sheet QoQ-Top 5 Brands
A3: Row Labels | B3: Count of MAKE
A4: Honda | B4: 260
A5: Q2 | B5: 66
A6: Q3 | B6: 93
A7: Q4 | B7: 101
A8: TVS | B8: 69
A9: Q3 | B9: 26
A10: Q4 | B10: 43
A11: Bajaj | B11: 54
A12: Q2 | B12: 15
A13: Q3 | B13: 20
A14: Q4 | B14: 19
A15: Hero | B15: 52
... A23: Grand Total | B23: 478

Sheet QoQ-Top 5 Models
A3: Row Labels | B3: Count of Model
A4: ACTIVA 110 | B4: 42
A5: Q2 | B5: 7
A6: Q3 | B6: 10
A7: Q4 | B7: 25
A8: ACTIVA | B8: 26
A9: Q2 | B9: 17
A10: Q3 | B10: 9
A11: Jupiter 110cc | B11: 17
A12: Q3 | B12: 4
A13: Q4 | B13: 13
A14: Activa 3G 110cc | B14: 17
A15: Q2 | B15: 1
... A21: Grand Total | B21: 117

Sheet Apr-Dec Consolidated
A1: Purchase Date | B1: Quarter | C1: VEHICLE NO | D1: MAKE | E1: Model | F1: Purchase Location | G1: PURCHASED FROM | H1: PURCHASE AMOUNT | I1: SELLER NAME
A2: 45438 | B2: Q2 | C2: MH12TX5747 | D2: Adventure 390CC BS6 | F2: KHARADI | H2: 15000
A3: 45385 | B3: Q2 | C3: MH14HH2582 | D3: APACHE | F3: RASTA PETH | G3: SACHIN | H3: 59000 | I3: MANOJ DEVRAM ZANJARE
A4: 45434 | B4: Q2 | C4: MH14JV0571 | D4: APACHE | F4: WAKAD | H4: 230000 | I4: ANURATH LALGE
A5: 45393 | B5: Q2 | C5: MH12RU6362 | D5: APACHE | E5: RTR 160 | F5: RASTA PETH | H5: 15000 | I5: KALYAN ADSULE
A6: 45496 | B6: Q3 | C6: MH12PG4377 | D6: APACHE | E6: RTR 200 4V | F6: UNDRI | H6: 50000
A7: 45513 | B7: Q3 | C7: MH12VD2809 | D7: Aprilia | E7: SXR 125 125CC | F7: RASTA PETH | H7: 14000
A8: 45419 | B8: Q2 | C8: MH14EB8337 | D8: AVIATOR | F8: RASTA PETH | G8: SACHIN | H8: 25000 | I8: KANTABAI VILAS GAJARE
A9: 45423 | B9: Q2 | C9: MH14CT3642 | D9: AVIATOR | F9: RASTA PETH | H9: 43000 | I9: AKASH VIKAS KIRTANE
A10: 45481 | B10: Q3 | C10: MH14EB8337 | D10: AVIATOR | F10: WAKAD | H10: 105000 | I10: SAMEER NIMKAR
A11: 45502 | B11: Q3 | C11: MH14FQ9898 | D11: AVIATOR | F11: WAKAD | H11: 28500 | I11: SOHEF SHARIFF
A12: 45474 | B12: Q3 | C12: MH14GJ9535 | D12: AVIATOR | F12: RASTA PETH | G12: HARSHAL | H12: 102000 | I12: BIMAL MOHAPATRA
A13: 45499 | B13: Q3 | C13: MH14JN0585 | D13: Bajaj | E13: AVENEGER 220 | F13: WAKAD | H13: 100000 | I13: KHEGARE SANTOSH PANDURANG
A14: 45437 | B14: Q2 | C14: MH14KV7736 | D14: Bajaj | E14: AVENGER 220 CRUISE | F14: RASTA PETH | G14: HARSHAL | H14: 70000 | I14: RAVIKUMAR RAMESHRAO WAGH
A15: 45390 | B15: Q2 | C15: MH12TF9335 | D15: Bajaj | E15: AVENGER 220 CRUISE | F15: WAKAD | G15: RAVI NANGARE | H15: 90000 | I15: AMMIT BORKAR
A16: 45430 | B16: Q2 | C16: MH12ND6857 | D16: Bajaj | E16: AVENGER 220 STREET | F16: WAKAD | H16: 32800 | I16: YAKUN IRANI
A17: 45486 | B17: Q3 | C17: MH12UT7785 | D17: Bajaj | E17: Avenger Street 160 ABS | F17: RASTA PETH | H17: 25000
A18: 45515 | B18: Q3 | C18: MH12JB4200 | D18: Bajaj | E18: Discover 125cc | F18: RASTA PETH | H18: 17500
A19: 45515 | B19: Q3 | C19: MH12RV6278 | D19: Bajaj | E19: Avenger Street 160 ABS | F19: RASTA PETH | H19: 33000
A20: 45517 | B20: Q3 | C20: MH12LB4818 | D20: Bajaj | E20: Pulsar LS 135cc | F20: RASTA PETH | H20: 70000
A21: 45520 | B21: Q3 | C21: MH12WW6560 | D21: Bajaj | E21: Pulsar N 250CC | F21: RASTA PETH | H21: 17500
A22: 45525 | B22: Q3 | C22: MH14DD9133 | D22: Bajaj | E22: Discover 100cc | F22: RASTA PETH | H22: 50000
A23: 45536 | B23: Q3 | C23: MH14LF7420 | D23: Bajaj | E23: Pulsar 220 DTS-I | F23: RASTA PETH | H23: 18300
A24: 45538 | B24: Q3 | C24: MH14DD2792 | D24: Bajaj | E24: Discover 150cc | F24: RASTA PETH | H24: 29500
A25: 45539 | B25: Q3 | C25: MH12TB6632 | D25: Bajaj | E25: Avenger Cruise 220 | F25: KHARADI | H25: 72000
A26: 45541 | B26: Q3 | C26: MH05CN3205 | D26: Bajaj | E26: Pulsar 220F | F26: WAKAD | H26: 11500
A27: 45547 | B27: Q3 | C27: MH14DP5749 | D27: Bajaj | E27: Discover 100cc | F27: RASTA PETH | H27: 45000
A28: 45554 | B28: Q3 | C28: MH14KL6082 | D28: Bajaj | E28: Pulsar NS 125cc | F28: RASTA PETH | H28: 275000
... A51: 45656 | B51: Q4 | C51: MH02CU4342 | D51: Bajaj | E51: Pulsar NS 200cc | F51: RASTA PETH | H51: 22000
A52: 45413 | B52: Q2 | C52: MH31DH6745 | D52: BAJAJ | E52: PULSAR | F52: RASTA PETH | G52: HARSHAL | H52: 17900 | I52: TUSHAR NIMJE
A53: 45448 | B53: Q2 | C53: MH12UB6179 | D53: BAJAJ | E53: Pulsar 150cc ABS | F53: KHARADI | H53: 57000
A54: 45414 | B54: Q2 | C54: MH12SM4401 | D54: BAJAJ | E54: Pulsar 150cc ABS FI BS6 | F54: KHARADI | H54: 158000
A55: 45390 | B55: Q2 | C55: MH12FM7433 | D55: BAJAJ | E55: PULSAR 180 | F55: WAKAD | G55: SACHIN | H55: 19000 | I55: NISHANT SINGH
A56: 45437 | B56: Q2 | C56: MH31DQ4787 | D56: BAJAJ | E56: PULSAR 180 | F56: RASTA PETH | G56: HARSHAL | H56: 22000 | I56: KARTIK KHEDULKAR
A57: 45390 | B57: Q2 | C57: MH12LR0449 | D57: BAJAJ | E57: PULSAR 220 | F57: RASTA PETH | G57: SACHIN | H57: 59000 | I57: NAVNATH KERU APHALE
A58: 45434 | B58: Q2 | C58: MH14DY6308 | D58: BAJAJ | E58: Pulsar 220 DTS-I | F58: KHARADI | H58: 60000
A59: 45466 | B59: Q2 | C59: MH12KV6958 | D59: BAJAJ | E59: Pulsar 220cc | F59: UNDRI | H59: 30000
A60: 45426 | B60: Q2 | C60: MH01BL0880 | D60: BAJAJ | E60: Pulsar NS 200cc | F60: UNDRI | H60: 11000
A61: 45432 | B61: Q2 | C61: MH12LG3782 | D61: BAJAJ | E61: Pulsar NS 200cc | F61: KHARADI | H61: 75000
A62: 45419 | B62: Q2 | C62: MH12PF9604 | D62: BAJAJ | E62: PULSAR RS | F62: RASTA PETH | H62: 99000 | I62: MR. SANMAY PV
...

Sheet MAY-24
A1: Purchase Date | B1: VEHICLE NO | C1: MAKE or MODEL | D1: Purchase Location | E1: PURCHASED FROM | F1: PURCHASE AMOUNT | G1: SELLER NAME
A2: 45413 | B2: MH12UD2292 | C2: CLASSIC 350 | D2: RASTA PETH | E2: HARSHAL | F2: 37000 | G2: Ankush Prabhakarrao Shivankar
A3: 45413 | B3: MH31DH6745 | C3: PULSAR | D3: RASTA PETH | E3: HARSHAL | F3: 17900 | G3: TUSHAR NIMJE
A4: 45414 | B4: MH12KK6144 | C4: ACTIVA 110 | D4: RASTA PETH | E4: HARSHAL | F4: 9500 | G4: MAYA MAHADEV KANADE
A5: 45414 | B5: MH12SM4401 | C5: Pulsar 150cc ABS FI BS6 | D5: KHARADI | F5: 158000
A6: 45415 | B6: MH14KE1650 | C6: SPLENDOR | D6: RASTA PETH | E6: SACHIN | F6: 51000 | G6: SANDEEP NARAYAN KAMBLE
A7: 45415 | B7: MH12RQ6261 | C7: Jupiter 110CC BS6 | D7: KHARADI | F7: 40000
A8: 45416 | B8: MH12TJ4040 | C8: BMW | D8: RASTA PETH | E8: HARSHAL | F8: 22800 | G8: VIJAY DINESH JOSHI
A9: 45416 | B9: MH17AQ0855 | C9: ACTIVA | D9: RASTA PETH | F9: 185000 | G9: POOJA SUDESH KULKARNI
A10: 45417 | B10: MH14GK5212 | C10: LETS | D10: RASTA PETH | E10: SACHIN | F10: 32500 | G10: GANESH SOMAJI BHUTE
A11: 45417 | B11: MH12JW4469 | C11: ACCESS 125 | D11: RASTA PETH | E11: SACHIN | F11: 24000 | G11: MUSSART MOHAMED HUSSAIN BAIG
A12: 45417 | B12: MH12RW5015 | C12: BMW G310 GS | D12: RASTA PETH | F12: 28000 | G12: MR- KEDAR PATURKAR
A13: 45417 | B13: MH14HT0571 | C13: RC 200CC ABS | D13: KHARADI | F13: 22000
A14: 45418 | B14: MH12JH9402 | C14: ACTIVA 110 | D14: RASTA PETH | E14: HARSHAL | F14: 53000 | G14: PAWAR ROHIT DANIEL
A15: 45418 | B15: MH12SP9842 | C15: Jupiter 110cc | D15: KHARADI | F15: 31300
A16: 45419 | B16: MH31DX0423 | C16: DIO | D16: RASTA PETH | E16: SACHIN | F16: 31500 | G16: MAYURI PRADIP CHARADE
A17: 45419 | B17: MH14EB8337 | C17: AVIATOR | D17: RASTA PETH | E17: SACHIN | F17: 25000 | G17: KANTABAI VILAS GAJARE
A18: 45419 | B18: MH12PF9604 | C18: PULSAR RS | D18: RASTA PETH | F18: 99000 | G18: MR. SANMAY PV
A19: 45422 | B19: MH14GJ8265 | C19: JUPITER | D19: RASTA PETH | E19: SACHIN | F19: 110000 | G19: ASLAM FIDAMOHAMMAD KHAN
A20: 45422 | B20: MH14EB6936 | C20: ACCESS 125 | D20: RASTA PETH | E20: SACHIN | F20: 44000 | G20: PRADEEP RAVINDRA ASADKAR
A21: 45422 | B21: MH12SS6438 | C21: SHINE-125 | D21: RASTA PETH | E21: SACHIN | F21: 58000 | G21: RAMDAS POPAT PAWAR
A22: 45422 | B22: MH14CY6284 | C22: ACTIVA | D22: RASTA PETH | E22: SACHIN | F22: 26500 | G22: RAJASHRI SATYAWAN DHURI
A23: 45422 | B23: MH12UL1178 | C23: DESTINI | D23: RASTA PETH | E23: HARSHAL | F23: 185000 | G23: VAISHALI ARUN PAWAR
A24: 45422 | B24: MH12LN0139 | C24: DREAMYUGA | D24: RASTA PETH | F24: 15000 | G24: DHUMAL SINDHU SANJOG
A25: 45423 | B25: MH14FH9942 | C25: PLATINA | D25: RASTA PETH | F25: 36000 | G25: SATISH NAGANATHAN IYER
A26: 45424 | B26: MH12MN7610 | C26: ACTIVA 3G | D26: RASTA PETH | E26: HARSHAL | F26: 13000 | G26: AISHWARYA ANANT JOSHI
A27: 45424 | B27: MH12NY9233 | C27: DIO SELF | D27: RASTA PETH | F27: 175000 | G27: SALMA BILAL SAUDAGAR
A28: 45425 | B28: MH12TQ6271 | C28: YZF R15 V3 | D28: RASTA PETH | F28: 43000 | G28: ROHAN SHILRATN MANE
A29: 45425 | B29: MH12GE2647 | C29: Pleasure | D29: RASTA PETH | F29: 21000 | G29: NARAYAN NAGAPPA RANE
A30: 45426 | B30: MH14FW5202 | C30: ACTIVA 3G | D30: RASTA PETH | E30: SACHIN | F30: 25000 | G30: PRATIBHA SRIRANG LAMA
A31: 45426 | B31: MH14CF4619 | C31: WEGO | D31: RASTA PETH | E31: SACHIN | F31: 32000 | G31: SAVITA KISHOR NALEGAVE
A32: 45426 | B32: MH14AR8020 | C32: ACTIVA | D32: RASTA PETH | E32: SACHIN | F32: 135000 | G32: NIRANJAN DEEPAK RANADE
A33: 45426 | B33: MH12RR5841 | C33: FZS | D33: RASTA PETH | E33: HARSHAL | F33: 20000 | G33: SWAPNILNEMA
A34: 45426 | B34: MH12PR1537 | C34: FASCINO | D34: RASTA PETH | F34: 22000 | G34: NAZIYA JAMEER SHAIKH
A35: 45426 | B35: MH01BL0880 | C35: Pulsar NS 200cc | D35: UNDRI | F35: 11000
A36: 45427 | B36: MH12SW9899 | C36: KTM | D36: RASTA PETH | E36: HARSHAL | F36: 130000 | G36: SUKRITI KUMAR
A37: 45427 | B37: MH12SP7786 | C37: Forty Two | D37: RASTA PETH | F37: 36500 | G37: SUFIYAN ANSARI
A38: 45428 | B38: MH14KX3078 | C38: HERO XOOM | D38: WAKAD | F38: 19000 | G38: CHANDRAKANT JADHAV
A39: 45428 | B39: MH47BC3782 | C39: YAMAHA R15 M | D39: WAKAD | F39: 100000 | G39: RAHUL KANOJIA
A40: 45428 | B40: MH12SR2011 | C40: PLATINA | D40: RASTA PETH | F40: 37000 | G40: MR ANIKET DONGARE
...

Sheet JUN-24
A1: Purchase Date | B1: VEHICLE NO | C1: MAKE or MODEL | D1: Purchase Location | E1: PURCHASED FROM | F1: PURCHASE AMOUNT | G1: SELLER NAME
A2: 45444 | B2: MH12JG9475 | D2: RASTA PETH | F2: 31000 | G2: VISHAL TEJRAO SAPKAL
A3: 45444 | B3: MH13CF5733 | C3: RC 200CC | D3: UNDRI | F3: 200000
A4: 45445 | B4: MH14JK3681 | C4: JUPITER | D4: RASTA PETH | E4: SACHIN | F4: 23000 | G4: AKHTARALI RUBABALI SAYYAD
A5: 45445 | B5: MH14FF1195 | C5: ACCESS 125 | D5: RASTA PETH | E5: SACHIN | F5: 172000 | G5: BHUSHAN HARISHCHANRA HINGMIRE
A6: 45445 | B6: MH14DD3607 | C6: ACTIVA | D6: RASTA PETH | E6: SACHIN | F6: 26000 | G6: SADANAND ANGARA PUJARI
A7: 45445 | B7: MH49Z8839 | C7: ACTIVA 3G | D7: RASTA PETH | E7: SACHIN | F7: 47500 | G7: HARSHAL VIJAY UMALE
A8: 45447 | B8: MH14JD1926 | C8: NS 200 | D8: WAKAD | F8: 50500 | G8: ISWARCHANDRA YADAV
A9: 45447 | B9: MH12QZ2731 | C9: Classic 350CC ABS Signals Dual Channel | D9: KHARADI | F9: 57000
A10: 45448 | B10: MH14JS6743 | C10: NS 200 | D10: WAKAD | F10: 90000 | G10: SABER SHEIKH
A11: 45448 | B11: MH12LM6537 | C11: ACTIVA | D11: RASTA PETH | E11: HARSHAL | F11: 35000 | G11: SUNITA GUPTA
A12: 45448 | B12: MH12KV0651 | C12: ACTIVA | D12: RASTA PETH | E12: HARSHAL | F12: 72000 | G12: CHHAYA ASHOK SHINDE
A13: 45448 | B13: MH12UB6179 | C13: Pulsar 150cc ABS | D13: KHARADI | F13: 57000
A14: 45449 | B14: MH14GG0755 | C14: hornet | D14: WAKAD | F14: 185000 | G14: MAYURESH GADGIL
A15: 45450 | B15: MH12RZ5264 | C15: ACTIVA 5G | D15: RASTA PETH | E15: HARSHAL | F15: 116500 | G15: JALANILA RAMU
A16: 45450 | B16: MH12TL2164 | C16: ACTIVA 6G | D16: RASTA PETH | E16: HARSHAL | F16: 200000 | G16: DHANASHREE DEVIDAS SONAWANE
A17: 45451 | B17: MH12PR3560 | C17: ns160 | D17: WAKAD | F17: 26500 | G17: DESHRAJ SINGH
A18: 45451 | B18: MH37P3882 | C18: Activa 110cc | D18: KHARADI | F18: 40600
A19: 45453 | B19: MH14ES0399 | C19: ACTIVA | D19: RASTA PETH | E19: SACHIN | F19: 45000 | G19: SATISHLAL POPATLAL KATARIYA
A20: 45453 | B20: MH14FL5823 | C20: VESPA | D20: RASTA PETH | E20: SACHIN | F20: 42000 | G20: VAISHALI SHRAVAN SONAWANE
A21: 45453 | B21: MH14FJ2561 | C21: UNICORN | D21: RASTA PETH | E21: SACHIN | F21: 25000 | G21: ROHAN SHAFI SHAIK
A22: 45453 | B22: MH12NG3874 | C22: JUPITER | D22: RASTA PETH | E22: HARSHAL | F22: 51000 | G22: ABHISHEK JAIN
A23: 45454 | B23: mh46m2976 | C23: access | D23: WAKAD | F23: 72000 | G23: mukesh gupta
A24: 45454 | B24: MH12VX8797 | C24: Splendor | D24: RASTA PETH | F24: 17000 | G24: JANHAVI KISHOR KSHIRSAGAR
A25: 45455 | B25: MH12NT4011 | C25: ACTIVA 3G | D25: RASTA PETH | E25: HARSHAL | F25: 21500 | G25: TANSOOR AALAM ANSARI
A26: 45455 | B26: MH12NG0699 | C26: ACTIVA 125 | D26: RASTA PETH | E26: HARSHAL | F26: 77000 | G26: RAKESH BHAUSHAEB KUNJII
A27: 45455 | B27: MH12UX9826 | C27: HUNTER 350 | D27: RASTA PETH | E27: HARSHAL | F27: 159500 | G27: KUNDAN KANHU WAGHCHAURE
A28: 45455 | B28: MH12PM3180 | D28: RASTA PETH | F28: 15000 | G28: ANSH GUPTA
A29: 45455 | B29: MH12WG1413 | D29: RASTA PETH | F29: 35000 | G29: AKSHAY MANE
A30: 45455 | B30: MH12GE2692 | C30: Passion Pro 100cc | D30: KHARADI | F30: 27000
A31: 45456 | B31: MH13BC6086 | C31: ACTIVA | D31: RASTA PETH | E31: HARSHAL | F31: 35000 | G31: KALE SAURABH GAJANAN
A32: 45456 | B32: MH14LN0259 | D32: RASTA PETH | F32: 15000 | G32: ABHISHEK RAMDAS AMBEKAR
A33: 45456 | B33: MH12QC7829 | C33: FZ25 250cc | D33: SINHAGAD ROAD | F33: 20000
A34: 45457 | B34: MH12SC2816 | C34: Activa 5G 110cc Standard | D34: KHARADI | F34: 45000
A35: 45458 | B35: MH14JS8656 | C35: SHINE | D35: RASTA PETH | E35: SACHIN | F35: 36000 | G35: PANKAJKUMAR YADAV
A36: 45458 | B36: MH14HB5055 | C36: ACTIVA 5G | D36: RASTA PETH | E36: SACHIN | F36: 142800 | G36: TANAJI LALASAHEB BHAGAT
A37: 45459 | B37: MH14JG0776 | C37: DUKE 125 | D37: RASTA PETH | E37: SACHIN | F37: 107000 | G37: AMOL ASHOK DESHMUKH
A38: 45459 | B38: MH14KG3797 | C38: SPLENDOR | D38: RASTA PETH | E38: SACHIN | F38: 59000 | G38: YOGESH BALJITSINGH YADAV
A39: 45461 | B39: MH12NM2162 | C39: CB Twister 110cc | D39: KHARADI | F39: 17000
A40: 45463 | B40: MH14JZ5038 | C40: RC 200 | D40: WAKAD | F40: 81000 | G40: RAJENDRA PAKNIKAR
...

Sheet JUL-24
A1: Purchase Date | B1: VEHICLE NO | C1: MAKE or MODEL | D1: Purchase Location | E1: PURCHASED FROM | F1: PURCHASE AMOUNT | G1: SELLER NAME
A2: 45474 | B2: MH14GT7104 | C2: GRAZIA | D2: RASTA PETH | E2: SACHIN | F2: 14000 | G2: SHIVRAJ CHANGUDE
A3: 45474 | B3: MH14CR5560 | C3: KARIZMA | D3: RASTA PETH | E3: SACHIN | F3: 65000 | G3: ANUP ROKI
A4: 45474 | B4: MH14ET2485 | D4: RASTA PETH | F4: 18300 | G4: GARVIT AGARWAL
A5: 45474 | B5: MH14GJ9535 | C5: AVIATOR | D5: RASTA PETH | E5: HARSHAL | F5: 102000 | G5: BIMAL MOHAPATRA
A6: 45474 | B6: MH12NF1990 | C6: ACTIVA 3G | D6: RASTA PETH | E6: HARSHAL | F6: 28500 | G6: JOHN NAIK
A7: 45474 | B7: MH12RS9621 | C7: CB Hornet 160R | D7: RASTA PETH | E7: HARSHAL | F7: 53500 | G7: XAVIER JOHN NAIK
A8: 45474 | B8: MH30BT6610 | C8: CB Unicorn160 160cc | D8: KHARADI | F8: 9100
A9: 45474 | B9: MH12ME1602 | C9: Activa 125 Alloy | D9: KHARADI | F9: 165000
A10: 45475 | B10: MH12SP4046 | C10: Activa 5G 110cc Standard | D10: KHARADI | F10: 65000
A11: 45476 | B11: MH14FH0328 | C11: GIXXER | D11: RASTA PETH | E11: SACHIN | F11: 32000 | G11: AKASH MANDAGE
A12: 45476 | B12: MH12WC5324 | C12: CB Hornet 160R | D12: RASTA PETH | F12: 42000 | G12: VIJAY BABAN WANJALE
A13: 45476 | B13: MH12TB6650 | C13: CB Unicorn160 160cc | D13: RASTA PETH | F13: 13000 | G13: MR MOHAMMAD HANZALA SHAIKH
A14: 45476 | B14: MH12FR1627 | C14: Activa 125 Alloy | D14: RASTA PETH | F14: 25000 | G14: JOSHI ARVIND
A15: 45476 | B15: MH12WG0952 | C15: Activa 5G 110cc Standard | D15: RASTA PETH | F15: 85000 | G15: SIDDHESH MUKUND CHAVHAN
A16: 45476 | B16: MH12RX5750 | C16: Jupiter 110CC BS6 | D16: SOMWAR PETH | F16: 72000
A17: 45477 | B17: MH14JK1638 | C17: PLEASURE | D17: RASTA PETH | E17: SACHIN | F17: 34300 | G17: PRAVIN GOSAVI
A18: 45479 | B18: MH14HH8171 | C18: DUET | D18: WAKAD | F18: 25000 | G18: VIPAL DILIP SWAMI
A19: 45479 | B19: MH41AK0099 | C19: KTM DUKE | D19: RASTA PETH | E19: HARSHAL | F19: 25000 | G19: ASHOK PAWAR
A20: 45479 | B20: MH12QK0118 | C20: Jupiter 110CC BS6 | D20: SOMWAR PETH | F20: 45000
A21: 45480 | B21: MH37Y2105 | C21: JUPITER | D21: WAKAD | F21: 27000 | G21: KUNAL LAL
A22: 45480 | B22: MH12LN1736 | D22: RASTA PETH | F22: 14000 | G22: JOSHI ASHUTOSH
A23: 45480 | B23: MH14FJ7804 | D23: RASTA PETH | F23: 145000
A24: 45480 | B24: MH12TW6532 | C24: SPLENDOR PLUS | D24: RASTA PETH | E24: HARSHAL | F24: 75000 | G24: SUNIL BHAGWAN KONALE
A25: 45480 | B25: MH12UD9863 | C25: PLATINA | D25: RASTA PETH | E25: HARSHAL | F25: 13500 | G25: SAMEER LAHU NIKAM
A26: 45481 | B26: MH14EB8337 | C26: AVIATOR | D26: WAKAD | F26: 105000 | G26: SAMEER NIMKAR
A27: 45481 | B27: MH14JF7514 | C27: ACTIVA | D27: RASTA PETH | E27: SACHIN | F27: 14000 | G27: PARVEEN SHAIKH
A28: 45481 | B28: MH15GW5597 | C28: RC 125CC | D28: UNDRI | F28: 36000
A29: 45481 | B29: MH12UT5610 | C29: Jupiter 110CC BS6 | D29: KHARADI | F29: 32000
A30: 45482 | B30: MH14JS3658 | C30: FZX | D30: WAKAD | F30: 177000 | G30: PRABHU SAI KRISHNA B
A31: 45482 | B31: MH14KT7109 | C31: BURGMAN | D31: WAKAD | F31: 173000 | G31: PRABHU SAI KRISHNA B
A32: 45482 | B32: MH12NM1312 | C32: DIO | D32: RASTA PETH | E32: HARSHAL | F32: 165000 | G32: SHUBHAM VINAYAK KELKAR
A33: 45483 | B33: MH12PY9808 | C33: ACCES | D33: RASTA PETH | E33: HARSHAL | F33: 50000 | G33: SADHANA CHAUHAN
A34: 45483 | B34: MH12KH0602 | C34: PLEASURE | D34: RASTA PETH | E34: HARSHAL | F34: 38000 | G34: RODRICKS AROCKYASWAMY
A35: 45485 | B35: MH14GK5166 | C35: DUKE 250 | D35: WAKAD | F35: 25000 | G35: SHUBHAM BANSAL
A36: 45485 | B36: MH42AU4969 | C36: VIKRANT | D36: RASTA PETH | E36: SACHIN | F36: 90000 | G36: UDAY JADHAV
A37: 45485 | B37: MH14EN9575 | C37: DISCOVER | D37: RASTA PETH | E37: SACHIN | F37: 20000 | G37: SHIVAJI SAMBHAJI TIKALE
A38: 45485 | B38: MH14BZ9443 | C38: ACTIVA | D38: RASTA PETH | E38: SACHIN | F38: 65000 | G38: ROSHNI MIRAJKAR
A39: 45485 | B39: MH12LU7337 | C39: CBR 150R 150CC | D39: SINHAGAD ROAD | F39: 28500
A40: 45485 | B40: MH12MJ8311 | C40: Activa I 110cc | D40: KHARADI | F40: 142000
...

Sheet AUG-24
A1: Purchase Date | B1: Reg No | C1: Make | D1: Purchase Location | E1: Model | F1: Purchase Price | G1: Channel | H1: Seller Type | I1: Inspection | J1: PDN No
A2: 45506 | B2: MH12WQ4898 | C2: Jawa | D2: ? | E2: 42 Bobber 330CC | F2: 152000 | G2: Walk-in | H2: Customer | I2: Store | J2: C07-P-100077
A3: 45506 | B3: MH12UH9147 | C3: Honda | D3: ? | E3: CB350 RS Dual Tone | F3: 65000 | G3: Walk-in | H3: Customer | I3: Store | J3: C02-P-100081
A4: 45507 | B4: MH12RD1033 | C4: Honda | D4: ? | E4: CB Hornet 160R ABS Deluxe | F4: 28000 | G4: Walk-in | H4: Customer | I4: Store | J4: F01-P-100086
A5: 45507 | B5: MH12LN6409 | C5: Royal Enfield | D5: ? | E5: Classic 350cc | F5: 166000 | G5: - | H5: Customer | I5: Store | J5: C01-P-100083
A6: 45508 | B6: MH14HV5141 | C6: TVS | D6: ? | E6: Radeon Drum | F6: 45500 | G6: Referral | H6: Customer | I6: Store | J6: F01-P-100087
A7: 45508 | B7: MH12LB0462 | C7: Honda | D7: ? | E7: Shine 125cc | F7: 31000 | G7: Referral | H7: Customer | I7: Store | J7: F01-P-100088
A8: 45509 | B8: MH14JZ7086 | C8: Suzuki | D8: ? | E8: Access Fi 125cc Disc alloy bluetooth BS6 | F8: 35300 | G8: Walk-in | H8: Customer | I8: Store | J8: C02-P-100082
A9: 45510 | B9: MH14HJ9889 | C9: TVS | D9: ? | E9: Jupiter 110cc | F9: 55000 | G9: OLX | H9: Customer | I9: Store | J9: C02-P-100083
A10: 45510 | B10: MH12LB6639 | C10: TVS | D10: ? | E10: Scooty Pep+ 90cc | F10: 40500 | G10: - | H10: Customer | I10: Store | J10: F01-P-100089
A11: 45511 | B11: MH14JK5260 | C11: Royal Enfield | D11: ? | E11: Classic 350 EFI | F11: 5000 | G11: Referral | H11: Customer | I11: Store | J11: F01-P-100090
A12: 45511 | B12: MH12LQ8651 | C12: Yamaha | D12: ? | E12: Ray 110cc | F12: 20000 | G12: Referral | H12: Agent | I12: Store | J12: F01-P-100091
A13: 45512 | B13: MH12VN7775 | C13: TVS | D13: ? | E13: Jupiter 110CC BS6 | F13: 45000 | G13: Google | H13: Customer | I13: Store | J13: C02-P-100084
... A93: 45535 | B93: MH12TJ6775 | C93: Hero | D93: ? | E93: Splendor Plus Self Alloy 100cc | F93: 59000 | G93: Walk-in | H93: Customer | I93: Store | J93: F01-P-100149

Sheet SEP-24
A1: Purchase Date | B1: Reg No | C1: Make | D1: Purchase Location | E1: Model | F1: Purchase Price | G1: Channel | H1: Seller Type | I1: Inspection | J1: PDN No
A2: 45536 | B2: MH22AE5820 | C2: Honda | D2: ? | E2: Activa I 110cc | F2: 52100 | G2: - | H2: Customer | I2: Store | J2: C02-P-100139
A3: 45536 | B3: MH14LF7420 | C3: Bajaj | D3: ? | E3: Pulsar 220 DTS-I | F3: 18300 | G3: Referral | H3: Agent | I3: Store | J3: F01-P-100150
A4: 45536 | B4: MH12QH9945 | C4: TVS | D4: ? | E4: NTorq 125 Standard | F4: 64000 | G4: - | H4: Agent | I4: Store | J4: F01-P-100151
A5: 45536 | B5: MH14JD1757 | C5: TVS | D5: ? | E5: Jupiter 110CC BS6 | F5: 43300 | G5: - | H5: Customer | I5: Store | J5: C02-P-100140
A6: 45536 | B6: MH14JS0411 | C6: Piaggio | D6: ? | E6: Vespa SXL 150cc | F6: 65000 | G6: Referral | H6: Customer | I6: Store | J6: F01-P-100154
A7: 45537 | B7: MH12VE3828 | C7: Royal Enfield | D7: ? | E7: Hunter 350 METRO REBEL | F7: 53000 | G7: - | H7: Customer | I7: Store | J7: C01-P-100145
A8: 45538 | B8: MH12UL0877 | C8: Hero | D8: ? | E8: Splendor Plus 100cc Black and Accent Edition | F8: 24215 | G8: Referral | H8: Customer | I8: Store | J8: F01-P-100162
A9: 45538 | B9: MH14EL4441 | C9: Honda | D9: ? | E9: Activa 110cc | F9: 47000 | G9: - | H9: Customer | I9: Store | J9: F01-P-100161
A10: 45538 | B10: MH12RZ8288 | C10: KTM | D10: ? | E10: RC 125CC | F10: 40000 | G10: - | H10: Customer | I10: Store | J10: F03-P-100051
A11: 45538 | B11: MH12NR0423 | C11: TVS | D11: ? | E11: Jupiter 110cc | F11: 159500 | G11: Website | H11: Customer | I11: Store | J11: F01-P-100164
A12: 45538 | B12: MH42X0842 | C12: Honda | D12: ? | E12: Dio 110cc | F12: 275000 | G12: Referral | H12: Customer | I12: Store | J12: F01-P-100157
A13: 45538 | B13: MH14GQ5183 | C13: Honda | D13: ? | E13: Activa 125 Standard | F13: 34000 | G13: Referral | H13: Customer | I13: Store | J13: F01-P-100165
... A91: 45565 | B91: MH12UP3324 | C91: TVS | D91: ? | E91: Jupiter 110cc ZX Disc SBT | F91: 47000 | G91: - | H91: Customer | I91: Store | J91: C01-P-100214

Sheet OCT-24
A1: Purchase Date | B1: Reg No | C1: Make | D1: Purchase Location | E1: Model | F1: Purchase Price | G1: Channel | H1: Seller Type | I1: Inspection | J1: PDN No
A2: 45566 | B2: MH14EW2475 | C2: Honda | D2: ? | E2: Activa 3G 110cc | F2: 28300 | G2: Referral | H2: Customer | I2: Store | J2: F01-P-100214
A3: 45567 | B3: MH14HZ9911 | C3: Hero | D3: ? | E3: Maestro Edge 125CC | F3: 43500 | G3: Referral | H3: Customer | I3: Store | J3: F01-P-100220
A4: 45569 | B4: MH14JS1793 | C4: Piaggio | D4: ? | E4: Vespa LX 125cc | F4: 91300 | G4: Google | H4: Customer | I4: Store | J4: C02-P-100212
A5: 45569 | B5: MH14EG1648 | C5: Hero | D5: ? | E5: Maestro Deluxe 110CC | F5: 26500 | G5: - | H5: Customer | I5: Store | J5: C01-P-100216
A6: 45570 | B6: MH14HF9813 | C6: TVS | D6: ? | E6: Jupiter ZX | F6: 5800 | G6: - | H6: Customer | I6: Store | J6: F01-P-100219
A7: 45571 | B7: MH12SM5184 | C7: Royal Enfield | D7: ? | E7: Classic 350 EFI | F7: 35000 | G7: - | H7: Customer | I7: Store | J7: F01-P-100216
A8: 45571 | B8: MH12WB8373 | C8: Royal Enfield | D8: ? | E8: Classic 350cc | F8: 22500 | G8: - | H8: Customer | I8: Store | J8: C01-P-100217
A9: 45571 | B9: MH12KL7019 | C9: Bajaj | D9: ? | E9: Avenger 220cc | F9: 38400 | G9: Zoho | H9: Customer | I9: Store | J9: C01-P-100218
A10: 45571 | B10: MH12LB0348 | C10: Honda | D10: ? | E10: Activa 110cc | F10: 30000 | G10: - | H10: Customer | I10: Store | J10: F01-P-100217
A11: 45572 | B11: MH12TF3803 | C11: TVS | D11: ? | E11: Jupiter ZX | F11: 31000 | G11: - | H11: Customer | I11: Store | J11: F01-P-100218
A12: 45572 | B12: MH12NR2585 | C12: TVS | D12: ? | E12: Jupiter 110cc | F12: 41000 | G12: - | H12: Customer | I12: Store | J12: C01-P-100219
A13: 45573 | B13: MH14JF3772 | C13: Piaggio | D13: ? | E13: Vespa LX 125cc | F13: 26500 | G13: Referral | H13: Customer | I13: Store | J13: F01-P-100225
... A103: 45596 | B103: MH12QX1463 | C103: Piaggio | D103: ? | E103: Vespa VXL 125cc | F103: 39000 | G103: Website | H103: Customer | I103: Store | J103: F01-P-100298

Sheet NOV-24
A1: Purchase Date | B1: Reg No | C1: Make | D1: Purchase Location | E1: Model | F1: Purchase Price | G1: Channel | H1: Seller Type | I1: Inspection | J1: PDN No
A2: 45597 | B2: MH12QU2001 | C2: Honda | D2: ? | E2: Activa 5G 110cc Deluxe | F2: 40000 | G2: - | H2: Customer | I2: Store | J2: C01-P-100302
A3: 45598 | B3: MH12UR0717 | C3: Hero | D3: ? | E3: HF Deluxe Self Ally I3s 100CC | F3: 24000 | G3: Referral | H3: Customer | I3: Store | J3: F01-P-100302
A4: 45598 | B4: MH12VD8436 | C4: Yamaha | D4: ? | E4: MT 15 150cc BS6 | F4: 35000 | G4: - | H4: Customer | I4: Store | J4: C01-P-100300
A5: 45599 | B5: MH12QD4034 | C5: Piaggio | D5: ? | E5: Vespa 125cc | F5: 26000 | G5: Referral | H5: Customer | I5: Store | J5: C02-P-100294
A6: 45599 | B6: MH12SV9671 | C6: KTM | D6: ? | E6: RC 125CC BS6 | F6: 130000 | G6: - | H6: Customer | I6: Store | J6: C01-P-100301
A7: 45600 | B7: MH05CT8650 | C7: TVS | D7: ? | E7: Jupiter 110cc | F7: 58000 | G7: - | H7: Customer | I7: Store | J7: C02-P-100295
A8: 45600 | B8: MH12UQ1149 | C8: TVS | D8: ? | E8: Jupiter 125 125cc Disc | F8: 27000 | G8: Website | H8: Customer | I8: Store | J8: C01-P-100303
A9: 45600 | B9: MH12HQ3820 | C9: Hero | D9: ? | E9: Passion Pro 100cc | F9: 62000 | G9: - | H9: Customer | I9: Store | J9: F01-P-100303
A10: 45601 | B10: MH12ST4741 | C10: TVS | D10: ? | E10: Apache RR 310 | F10: 18500 | G10: - | H10: Customer | I10: Store | J10: F01-P-100312
A11: 45601 | B11: MH14JY0236 | C11: Hero | D11: ? | E11: Splendor Plus 100cc | F11: 31000 | G11: Referral | H11: Customer | I11: Store | J11: F01-P-100306
A12: 45601 | B12: MH14FN6792 | C12: Honda | D12: ? | E12: Activa 3G 110cc | F12: 27000 | G12: Referral | H12: Customer | I12: Store | J12: F01-P-100305
A13: 45601 | B13: MH14EX2596 | C13: Honda | D13: ? | E13: Activa 3G 110cc | F13: 36500 | G13: Referral | H13: Customer | I13: Store | J13: F01-P-100307
... A62: 45626 | B62: MH18BP3399 | C62: Yamaha | D62: ? | E62: YZF R15 150cc | F62: 15000 | G62: - | H62: Customer | I62: Store | J62: F01-P-100368

Sheet DEC-24
A1: Purchase Date | B1: Reg No | C1: Make | D1: Purchase Location | E1: Model | F1: Purchase Price | G1: Channel | H1: Seller Type | I1: Inspection | J1: PDN No
A2: 45627 | B2: MH14GR3605 | C2: Hero | D2: ? | E2: Passion Pro I3s Alloy 100cc | F2: 56600 | G2: - | H2: Customer | I2: Store | J2: F01-P-100353
A3: 45627 | B3: MH14ES7409 | C3: Bajaj | D3: ? | E3: Discover F 150cc | F3: 75000 | G3: - | H3: Customer | I3: Store | J3: F01-P-100352
A4: 45627 | B4: MH14CZ3532 | C4: Honda | D4: ? | E4: Activa 110cc | F4: 80000 | G4: Referral | H4: Customer | I4: Store | J4: F01-P-100347
A5: 45627 | B5: MH18AQ7064 | C5: Hero | D5: ? | E5: Passion XPro 110cc | F5: 81000 | G5: - | H5: Customer | I5: Store | J5: F01-P-100357
A6: 45627 | B6: MH14HF2576 | C6: Hero | D6: ? | E6: Duet LX 110cc | F6: 30000 | G6: - | H6: Customer | I6: Store | J6: F01-P-100356
A7: 45627 | B7: MH12NZ9933 | C7: Bajaj | D7: ? | E7: Pulsar 220 DTS-I | F7: 22000 | G7: - | H7: Customer | I7: Store | J7: F01-P-100349
A8: 45627 | B8: MH12VP3881 | C8: TVS | D8: ? | E8: Scooty Zest 110cc | F8: 25000 | G8: - | H8: Customer | I8: Store | J8: F01-P-100358
A9: 45627 | B9: MH14FW8078 | C9: Piaggio | D9: ? | E9: Vespa SXL 150cc | F9: 5000 | G9: - | H9: Customer | I9: Store | J9: F01-P-100350
A10: 45627 | B10: MH14FN4682 | C10: Yamaha | D10: ? | E10: FZS 150cc | F10: 145000 | G10: - | H10: Customer | I10: Store | J10: F01-P-100348
A11: 45627 | B11: MH12MZ6239 | C11: Honda | D11: ? | E11: Activa 3G 110cc | F11: 100000 | G11: Referral | H11: Customer | I11: Store | J11: F01-P-100351
A12: 45627 | B12: MH14DZ7878 | C12: Piaggio | D12: ? | E12: Vespa 125cc | F12: 20000 | G12: - | H12: Customer | I12: Store | J12: F01-P-100355
A13: 45627 | B13: MH14HR0344 | C13: Honda | D13: ? | E13: Activa 5G 110cc Standard | F13: 41000 | G13: - | H13: Customer | I13: Store | J13: F01-P-100354
... A77: 45657 | B77: MH12VH3859 | C77: Royal Enfield | D77: ? | E77: Bullet 350cc KS EFI Black | F77: 135000 | G77: Walk-in | H77: Customer | I77: Store | J77: F01-P-100412

Sheet Store Code
A1: Store Location | B1: Store Purchase ID
A2: SINHAGAD ROAD | B2: C08
A3: SOMWAR PETH | B3: C07
A4: UNDRI | B4: F03
A5: MAGARPATTA | B5: C06
A6: PAUD ROAD | B6: C03
A7: RASTA PETH | B7: F01
A8: KHARADI | B8: C01
A9: WAKAD | B9: C02
